Workbook

Sheet IE
C2: EVALUACIÓN DIAGNÓSTICA INSTITUCIÓN EDUCATIVA: 40079 "Víctor Núñez Valencia" DISTRITO SACHACA
C3: Nivel de logro de las competencias
F4: MATEMÁTICA | J4: COMUNICACIÓN | M4: CIENCIA Y TECNOLOGÍA | P4: CIENCIAS SOCIALES | S4: DPCC | U4: EPT | V4: EDUCACIÓN FÍSICA | Y4: ARTE Y CULTURA | AA4: INGLES | AD4: EDUCACIÓN RELIGIOSA
C5: APELLIDOS Y NOMBRES DEL ESTUDIANTE | D5: GRADO | E5: SECCION | F5: C1 | G5: C2 | H5: C3 | I5: C4 | J5: C1 | K5: C2 | L5: C3 | M5: C1 | N5: C2 | O5: C3 | P5: C1 | Q5: C2 | R5: C3 | S5: C1 | T5: C2 | U5: C1 | V5: C1 | W5: C2 | X5: C3 | Y5: C1 | Z5: C2 | AA5: C1 | AB5: C2 | AC5: C3 | AD5: C1 | AE5: C2
A6: 1 | B6: 1 | C6: ALEJO LUPINTA, DIANA ABIGAIL | D6: 1 | E6: A | F6: A | G6: A | H6: B | I6: A | J6: A | K6: A | L6: A | M6: A | N6: A | O6: A | P6: A | Q6: B | R6: B | S6: A | T6: A | U6: A | V6: A | W6: A | X6: A | Y6: B | Z6: A | AA6: B | AB6: B | AC6: A | AD6: A | AE6: B
A7: 2 | B7: 2 | C7: ARCONDO HUAMAN, ISAAC RONALDINHO | D7: 1 | E7: A | F7: B | G7: C | H7: B | I7: B | J7: B | K7: B | L7: B | M7: B | N7: B | O7: C | P7: B | Q7: B | R7: B | S7: C | T7: C | U7: B | V7: B | W7: B | X7: A | Y7: B | Z7: A | AA7: C | AB7: C | AC7: C | AD7: C | AE7: B
A8: 3 | B8: 3 | C8: BALSA MAMANI, JHOSUE SAJAAT | D8: 1 | E8: A | F8: A | G8: A | H8: A | I8: A | J8: A | K8: A | L8: A | M8: A | N8: A | O8: A | P8: A | Q8: A | R8: B | S8: A | T8: A | U8: A | V8: A | W8: A | X8: A | Y8: A | Z8: A | AA8: A | AB8: B | AC8: B | AD8: A | AE8: B
A9: 4 | B9: 4 | C9: CALANCHO MAMANI, RIZIERI BEAUTY | D9: 1 | E9: A | F9: A | G9: B | H9: B | I9: B | J9: A | K9: A | L9: A | M9: B | N9: B | O9: A | P9: A | Q9: A | R9: B | S9: A | T9: B | U9: A | V9: B | W9: A | X9: A | Y9: B | Z9: A | AA9: B | AB9: B | AC9: B | AD9: A | AE9: B
A10: 5 | B10: 5 | C10: CHAMPE TACO, JUMY JAHAIRA | D10: 1 | E10: A | F10: B | G10: B | H10: B | I10: B | J10: A | K10: A | L10: A | M10: A | N10: B | O10: A | P10: B | Q10: B | R10: B | S10: A | T10: B | U10: B | V10: A | W10: B | X10: A | Y10: B | Z10: A | AA10: B | AB10: B | AC10: C | AD10: B | AE10: B
A11: 6 | B11: 6 | C11: CUTI SENCIA, AIXA AYSEL | D11: 1 | E11: A | F11: A | G11: A | H11: A | I11: A | J11: A | K11: A | L11: A | M11: A | N11: A | O11: A | P11: A | Q11: B | R11: B | S11: A | T11: B | U11: B | V11: B | W11: A | X11: A | Y11: A | Z11: B | AA11: B | AB11: B | AC11: B | AD11: B | AE11: B
A12: 7 | B12: 7 | C12: HUACARPUMA SULCA, BRITNEY ESTEFANY | D12: 1 | E12: A | F12: A | G12: A | H12: B | I12: A | J12: A | K12: A | L12: A | M12: A | N12: A | O12: A | P12: A | Q12: A | R12: A | S12: A | T12: A | U12: B | V12: A | W12: A | X12: A | Y12: A | Z12: A | AA12: A | AB12: B | AC12: A | AD12: B | AE12: B
A13: 8 | B13: 8 | C13: MAMANI CHALLCO, LENIN ANDRÉ | D13: 1 | E13: A | F13: B | G13: C | H13: B | I13: B | J13: B | K13: B | L13: B | M13: B | N13: B | O13: B | P13: B | Q13: B | R13: B | S13: C | T13: B | U13: B | V13: A | W13: B | X13: A | Y13: B | Z13: B | AA13: B | AB13: C | AC13: C | AD13: C | AE13: B
A14: 9 | B14: 9 | C14: MANTILLA MAYTA, BELINDA MAJU | D14: 1 | E14: A | F14: B | G14: B | H14: C | I14: B | J14: A | K14: A | L14: A | M14: A | N14: B | O14: A | P14: B | Q14: B | R14: B | S14: B | T14: A | U14: B | V14: B | W14: A | X14: A | Y14: B | Z14: A | AA14: B | AB14: B | AC14: C | AD14: A | AE14: B
A15: 10 | B15: 10 | C15: MOROCCO CCALLO, YOSELIN RUTH | D15: 1 | E15: A | F15: B | G15: B | H15: B | I15: B | J15: B | K15: B | L15: B | M15: B | N15: B | O15: A | P15: B | Q15: B | R15: B | S15: A | T15: B | U15: B | V15: A | W15: A | X15: A | Y15: B | Z15: A | AA15: B | AB15: B | AC15: C | AD15: B | AE15: B
A16: 11 | B16: 11 | C16: NINA CHUMBES, ARIANA NIKOL | D16: 1 | E16: A | F16: B | G16: B | H16: B | I16: B | J16: A | K16: A | L16: A | M16: B | N16: B | O16: A | P16: B | Q16: B | R16: C | S16: B | T16: A | U16: B | V16: A | W16: B | X16: A | Y16: A | Z16: A | AA16: B | AB16: B | AC16: C | AD16: B | AE16: B
A17: 12 | B17: 12 | C17: OCHOA MAMANI, ARELÍ BETSAYDA | D17: 1 | E17: A | F17: B | G17: B | H17: B | I17: C | J17: B | K17: B | L17: B | M17: B | N17: B | O17: B | P17: B | Q17: B | R17: B | S17: C | T17: C | U17: B | V17: B | W17: B | X17: A | Y17: A | Z17: A | AA17: C | AB17: C | AC17: C | AD17: C | AE17: B
... A232: 227 | B232: 26 | C232: ZARAVIA JARAMILLO, GRACE SAMARA | D232: 5 | E232: B | F232: AD | G232: A | H232: A | I232: A | J232: A | K232: A | L232: A | M232: A | N232: A | O232: A | P232: B | Q232: A | R232: A | S232: A | T232: A | U232: A | V232: A | W232: A | X232: A | Y232: A | Z232: A | AA232: A | AB232: A | AC232: A | AD232: A | AE232: B
C235: MAPAS DE CALOR | F235: 1 | G235: 2 | H235: 3 | I235: 4 | J235: 5 | K235: 6 | L235: 7 | M235: 8 | N235: 9 | O235: 10 | P235: 11 | Q235: 12 | R235: 13 | S235: 14 | T235: 15 | U235: 16 | V235: 17 | W235: 18 | X235: 19 | Y235: 20 | Z235: 21 | AA235: 22 | AB235: 23 | AC235: 24 | AD235: 25 | AE235: 26
C236: INICIO C | F236: =COUNTIF(F6:F231,"C") -> 27 | G236: =COUNTIF(G6:G231,"C") -> 43 | H236: =COUNTIF(H6:H231,"C") -> 31 | I236: =COUNTIF(I6:I231,"C") -> 17 | J236: =COUNTIF(J6:J231,"C") -> 3 | K236: =COUNTIF(K6:K231,"C") -> 7 | L236: =COUNTIF(L6:L231,"C") -> 4 | M236: =COUNTIF(M6:M231,"C") -> 7 | ... AE236: =COUNTIF(AE6:AE231,"C") -> 0
C237: PROCESO B | F237: =COUNTIF(F6:F231,"B") -> 95 | G237: =COUNTIF(G6:G231,"B") -> 94 | H237: =COUNTIF(H6:H231,"B") -> 110 | I237: =COUNTIF(I6:I231,"B") -> 112 | J237: =COUNTIF(J6:J231,"B") -> 86 | K237: =COUNTIF(K6:K231,"B") -> 91 | L237: =COUNTIF(L6:L231,"B") -> 123 | M237: =COUNTIF(M6:M231,"B") -> 89 | ... AE237: =COUNTIF(AE6:AE231,"B") -> 219
C238: LOGRO A | F238: =COUNTIF(F6:F231,"A") -> 91 | G238: =COUNTIF(G6:G231,"A") -> 84 | H238: =COUNTIF(H6:H231,"A") -> 75 | I238: =COUNTIF(I6:I231,"A") -> 83 | J238: =COUNTIF(J6:J231,"A") -> 132 | K238: =COUNTIF(K6:K231,"A") -> 117 | L238: =COUNTIF(L6:L231,"A") -> 96 | M238: =COUNTIF(M6:M231,"A") -> 130 | ... AE238: =COUNTIF(AE6:AE231,"A") -> 0
C239: LOGRO DESTACADO AD | F239: =COUNTIF(F6:F231,"AD") -> 13 | G239: =COUNTIF(G6:G231,"AD") -> 5 | H239: =COUNTIF(H6:H231,"AD") -> 10 | I239: =COUNTIF(I6:I231,"AD") -> 14 | J239: =COUNTIF(J6:J231,"AD") -> 5 | K239: =COUNTIF(K6:K231,"AD") -> 11 | L239: =COUNTIF(L6:L231,"AD") -> 3 | M239: =COUNTIF(M6:M231,"AD") -> 0 | ... AE239: =COUNTIF(AE6:AE231,"AD") -> 0

Sheet Por áreas
B27: MATEMÁTICA | C27: C1 | D27: C2 | E27: C3 | F27: C4 | J27: COMUNICACIÓN | K27: C1 | L27: C2 | M27: C3 | R27: CIENCIA Y TECNOLOGÍA | S27: C1 | T27: C2 | U27: C3 | AA27: CIENCIAS SOCIALES | AB27: C1 | AC27: C2 | AD27: C3 | AH27: DPCC | AI27: C1 | AJ27: C2 | AM27: EPT | AN27: C1 | AS27: ED.FÍSICA | AT27: C1 | AU27: C2 | AV27: C3 | BB27: ARTE | BC27: C1 | BD27: C2 | BJ27: INGLÉS | BK27: C1 | BL27: C2 | BM27: C3 | BR27: RELIGIÓN | BS27: C1 | BT27: C2
B28: INICIO C | C28: =IE!F236 -> 27 | D28: =IE!G236 -> 43 | E28: =IE!H236 -> 31 | F28: =IE!I236 -> 17 | J28: INICIO C | K28: =IE!J236 -> 3 | L28: =IE!K236 -> 7 | M28: =IE!L236 -> 4 | R28: INICIO C | S28: =IE!M236 -> 7 | T28: =IE!N236 -> 7 | U28: =IE!O236 -> 14 | AA28: INICIO C | AB28: =IE!P236 -> 27 | AC28: =IE!Q236 -> 20 | AD28: =IE!R236 -> 19 | AH28: INICIO C | AI28: =IE!S236 -> 28 | AJ28: =IE!T236 -> 22 | AM28: INICIO C | AN28: =IE!U236 -> 0 | AS28: INICIO C | AT28: =IE!V236 -> 0 | AU28: =IE!W236 -> 0 | AV28: =IE!X236 -> 0 | BB28: INICIO C | BC28: =IE!Y236 -> 13 | BD28: =IE!Z236 -> 5 | BJ28: INICIO C | BK28: =IE!AA236 -> 18 | BL28: =IE!AB236 -> 13 | BM28: =IE!AC236 -> 25 | BR28: INICIO C | BS28: =IE!AD236 -> 56 | BT28: =IE!AE236 -> 0
B29: PROCESO B | C29: =IE!F237 -> 95 | D29: =IE!G237 -> 94 | E29: =IE!H237 -> 110 | F29: =IE!I237 -> 112 | J29: PROCESO B | K29: =IE!J237 -> 86 | L29: =IE!K237 -> 91 | M29: =IE!L237 -> 123 | R29: PROCESO B | S29: =IE!M237 -> 89 | T29: =IE!N237 -> 76 | U29: =IE!O237 -> 49 | AA29: PROCESO B | AB29: =IE!P237 -> 129 | AC29: =IE!Q237 -> 136 | AD29: =IE!R237 -> 138 | AH29: PROCESO B | AI29: =IE!S237 -> 71 | AJ29: =IE!T237 -> 81 | AM29: PROCESO B | AN29: =IE!U237 -> 97 | AS29: PROCESO B | AT29: =IE!V237 -> 62 | AU29: =IE!W237 -> 56 | AV29: =IE!X237 -> 52 | BB29: PROCESO B | BC29: =IE!Y237 -> 75 | BD29: =IE!Z237 -> 66 | BJ29: PROCESO B | BK29: =IE!AA237 -> 110 | BL29: =IE!AB237 -> 111 | BM29: =IE!AC237 -> 98 | BR29: PROCESO B | BS29: =IE!AD237 -> 69 | BT29: =IE!AE237 -> 219
B30: LOGRO A | C30: =IE!F238 -> 91 | D30: =IE!G238 -> 84 | E30: =IE!H238 -> 75 | F30: =IE!I238 -> 83 | J30: LOGRO A | K30: =IE!J238 -> 132 | L30: =IE!K238 -> 117 | M30: =IE!L238 -> 96 | R30: LOGRO A | S30: =IE!M238 -> 130 | T30: =IE!N238 -> 143 | U30: =IE!O238 -> 163 | AA30: LOGRO A | AB30: =IE!P238 -> 70 | AC30: =IE!Q238 -> 70 | AD30: =IE!R238 -> 69 | AH30: LOGRO A | AI30: =IE!S238 -> 127 | AJ30: =IE!T238 -> 123 | AM30: LOGRO A | AN30: =IE!U238 -> 129 | AS30: LOGRO A | AT30: =IE!V238 -> 164 | AU30: =IE!W238 -> 170 | AV30: =IE!X238 -> 174 | BB30: LOGRO A | BC30: =IE!Y238 -> 133 | BD30: =IE!Z238 -> 147 | BJ30: LOGRO A | BK30: =IE!AA238 -> 95 | BL30: =IE!AB238 -> 101 | BM30: =IE!AC238 -> 102 | BR30: LOGRO A | BS30: =IE!AD238 -> 94 | BT30: =IE!AE238 -> 0
B31: LOGRO DESTACADO AD | C31: =IE!F239 -> 13 | D31: =IE!G239 -> 5 | E31: =IE!H239 -> 10 | F31: =IE!I239 -> 14 | J31: LOGRO DESTACADO AD | K31: =IE!J239 -> 5 | L31: =IE!K239 -> 11 | M31: =IE!L239 -> 3 | R31: LOGRO DESTACADO AD | S31: =IE!M239 -> 0 | T31: =IE!N239 -> 0 | U31: =IE!O239 -> 0 | AA31: LOGRO DESTACADO AD | AB31: =IE!P239 -> 0 | AC31: =IE!Q239 -> 0 | AD31: =IE!R239 -> 0 | AH31: LOGRO DESTACADO AD | AI31: =IE!S239 -> 0 | AJ31: =IE!T239 -> 0 | AM31: LOGRO DESTACADO AD | AN31: =IE!U239 -> 0 | AS31: LOGRO DESTACADO AD | AT31: =IE!V239 -> 0 | AU31: =IE!W239 -> 0 | AV31: =IE!X239 -> 0 | BB31: LOGRO DESTACADO AD | BC31: =IE!Y239 -> 5 | BD31: =IE!Z239 -> 8 | BJ31: LOGRO DESTACADO AD | BK31: =IE!AA239 -> 3 | BL31: =IE!AB239 -> 1 | BM31: =IE!AC239 -> 1 | BR31: LOGRO DESTACADO AD | BS31: =IE!AD239 -> 0 | BT31: =IE!AE239 -> 0

Sheet Reforzamiento
B2: EVALUACIÓN DIAGNÓSTICA INSTITUCIÓN EDUCATIVA: 40079 "Víctor Núñez Valencia" DISTRITO SACHACA
B3: Nivel de logro de las competencias
E4: MATEMÁTICA | I4: COMUNICACIÓN | L4: CIENCIA Y TECNOLOGÍA | O4: CIENCIAS SOCIALES | R4: DPCC | T4: EPT | U4: EDUCACIÓN FÍSICA | X4: ARTE Y CULTURA | Z4: INGLES | AC4: EDUCACIÓN RELIGIOSA
B5: APELLIDOS Y NOMBRES DEL ESTUDIANTE | C5: GRADO | D5: SECCION | E5: C1 | F5: C2 | G5: C3 | H5: C4 | I5: C1 | J5: C2 | K5: C3 | L5: C1 | M5: C2 | N5: C3 | O5: C1 | P5: C2 | Q5: C3 | R5: C1 | S5: C2 | T5: C1 | U5: C1 | V5: C2 | W5: C3 | X5: C1 | Y5: C2 | Z5: C1 | AA5: C2 | AB5: C3 | AC5: C1 | AD5: C2 | AE5: RR
A6: 1 | B6: ALEJO LUPINTA, DIANA ABIGAIL | C6: 1 | D6: A | E6: A | F6: A | G6: B | H6: A | I6: A | J6: A | K6: A | L6: A | M6: A | N6: A | O6: A | P6: B | Q6: B | R6: A | S6: A | T6: A | U6: A | V6: A | W6: A | X6: B | Y6: A | Z6: B | AA6: B | AB6: A | AC6: A | AD6: B | AE6: =+COUNTIF(E6:AD6,"C") -> 0
A7: 2 | B7: ARCONDO HUAMAN, ISAAC RONALDINHO | C7: 1 | D7: A | E7: B | F7: C | G7: B | H7: B | I7: B | J7: B | K7: B | L7: B | M7: B | N7: C | O7: B | P7: B | Q7: B | R7: C | S7: C | T7: B | U7: B | V7: B | W7: A | X7: B | Y7: A | Z7: C | AA7: C | AB7: C | AC7: C | AD7: B | AE7: =+COUNTIF(E7:AD7,"C") -> 8
A8: 3 | B8: BALSA MAMANI, JHOSUE SAJAAT | C8: 1 | D8: A | E8: A | F8: A | G8: A | H8: A | I8: A | J8: A | K8: A | L8: A | M8: A | N8: A | O8: A | P8: A | Q8: B | R8: A | S8: A | T8: A | U8: A | V8: A | W8: A | X8: A | Y8: A | Z8: A | AA8: B | AB8: B | AC8: A | AD8: B | AE8: =+COUNTIF(E8:AD8,"C") -> 0
A9: 4 | B9: CALANCHO MAMANI, RIZIERI BEAUTY | C9: 1 | D9: A | E9: A | F9: B | G9: B | H9: B | I9: A | J9: A | K9: A | L9: B | M9: B | N9: A | O9: A | P9: A | Q9: B | R9: A | S9: B | T9: A | U9: B | V9: A | W9: A | X9: B | Y9: A | Z9: B | AA9: B | AB9: B | AC9: A | AD9: B | AE9: =+COUNTIF(E9:AD9,"C") -> 0
A10: 5 | B10: CHAMPE TACO, JUMY JAHAIRA | C10: 1 | D10: A | E10: B | F10: B | G10: B | H10: B | I10: A | J10: A | K10: A | L10: A | M10: B | N10: A | O10: B | P10: B | Q10: B | R10: A | S10: B | T10: B | U10: A | V10: B | W10: A | X10: B | Y10: A | Z10: B | AA10: B | AB10: C | AC10: B | AD10: B | AE10: =+COUNTIF(E10:AD10,"C") -> 1
A11: 6 | B11: CUTI SENCIA, AIXA AYSEL | C11: 1 | D11: A | E11: A | F11: A | G11: A | H11: A | I11: A | J11: A | K11: A | L11: A | M11: A | N11: A | O11: A | P11: B | Q11: B | R11: A | S11: B | T11: B | U11: B | V11: A | W11: A | X11: A | Y11: B | Z11: B | AA11: B | AB11: B | AC11: B | AD11: B | AE11: =+COUNTIF(E11:AD11,"C") -> 0
A12: 7 | B12: HUACARPUMA SULCA, BRITNEY ESTEFANY | C12: 1 | D12: A | E12: A | F12: A | G12: B | H12: A | I12: A | J12: A | K12: A | L12: A | M12: A | N12: A | O12: A | P12: A | Q12: A | R12: A | S12: A | T12: B | U12: A | V12: A | W12: A | X12: A | Y12: A | Z12: A | AA12: B | AB12: A | AC12: B | AD12: B | AE12: =+COUNTIF(E12:AD12,"C") -> 0
A13: 8 | B13: MAMANI CHALLCO, LENIN ANDRÉ | C13: 1 | D13: A | E13: B | F13: C | G13: B | H13: B | I13: B | J13: B | K13: B | L13: B | M13: B | N13: B | O13: B | P13: B | Q13: B | R13: C | S13: B | T13: B | U13: A | V13: B | W13: A | X13: B | Y13: B | Z13: B | AA13: C | AB13: C | AC13: C | AD13: B | AE13: =+COUNTIF(E13:AD13,"C") -> 5
A14: 9 | B14: MANTILLA MAYTA, BELINDA MAJU | C14: 1 | D14: A | E14: B | F14: B | G14: C | H14: B | I14: A | J14: A | K14: A | L14: A | M14: B | N14: A | O14: B | P14: B | Q14: B | R14: B | S14: A | T14: B | U14: B | V14: A | W14: A | X14: B | Y14: A | Z14: B | AA14: B | AB14: C | AC14: A | AD14: B | AE14: =+COUNTIF(E14:AD14,"C") -> 2
A15: 10 | B15: MOROCCO CCALLO, YOSELIN RUTH | C15: 1 | D15: A | E15: B | F15: B | G15: B | H15: B | I15: B | J15: B | K15: B | L15: B | M15: B | N15: A | O15: B | P15: B | Q15: B | R15: A | S15: B | T15: B | U15: A | V15: A | W15: A | X15: B | Y15: A | Z15: B | AA15: B | AB15: C | AC15: B | AD15: B | AE15: =+COUNTIF(E15:AD15,"C") -> 1
A16: 11 | B16: NINA CHUMBES, ARIANA NIKOL | C16: 1 | D16: A | E16: B | F16: B | G16: B | H16: B | I16: A | J16: A | K16: A | L16: B | M16: B | N16: A | O16: B | P16: B | Q16: C | R16: B | S16: A | T16: B | U16: A | V16: B | W16: A | X16: A | Y16: A | Z16: B | AA16: B | AB16: C | AC16: B | AD16: B | AE16: =+COUNTIF(E16:AD16,"C") -> 2
A17: 12 | B17: OCHOA MAMANI, ARELÍ BETSAYDA | C17: 1 | D17: A | E17: B | F17: B | G17: B | H17: C | I17: B | J17: B | K17: B | L17: B | M17: B | N17: B | O17: B | P17: B | Q17: B | R17: C | S17: C | T17: B | U17: B | V17: B | W17: A | X17: A | Y17: A | Z17: C | AA17: C | AB17: C | AC17: C | AD17: B | AE17: =+COUNTIF(E17:AD17,"C") -> 7
... A231: 25 | B231: VILLANUEVA CHAVEZ, MILAGROS FRANCHESCA | C231: 5 | D231: B | E231: B | F231: B | G231: B | H231: B | I231: B | J231: B | K231: B | L231: A | M231: B | N231: A | O231: B | P231: B | Q231: B | R231: B | S231: A | T231: B | U231: B | V231: B | W231: B | X231: A | Y231: B | Z231: B | AA231: B | AB231: B | AC231: B | AD231: B | AE231: =+COUNTIF(E231:AD231,"C") -> 0
A232: 26 | B232: ZARAVIA JARAMILLO, GRACE SAMARA | C232: 5 | D232: B | E232: AD | F232: A | G232: A | H232: A | I232: A | J232: A | K232: A | L232: A | M232: A | N232: A | O232: B | P232: A | Q232: A | R232: A | S232: A | T232: A | U232: A | V232: A | W232: A | X232: A | Y232: A | Z232: A | AA232: A | AB232: A | AC232: A | AD232: B
B235: MAPAS DE CALOR | E235: 1 | F235: 2 | G235: 3 | H235: 4 | I235: 5 | J235: 6 | K235: 7 | L235: 8 | M235: 9 | N235: 10 | O235: 11 | P235: 12 | Q235: 13 | R235: 14 | S235: 15 | T235: 16 | U235: 17 | V235: 18 | W235: 19 | X235: 20 | Y235: 21 | Z235: 22 | AA235: 23 | AB235: 24 | AC235: 25 | AD235: 26
B236: INICIO C | E236: =COUNTIF(E6:E231,"C") -> 27 | F236: =COUNTIF(F6:F231,"C") -> 43 | G236: =COUNTIF(G6:G231,"C") -> 31 | H236: =COUNTIF(H6:H231,"C") -> 17 | I236: =COUNTIF(I6:I231,"C") -> 3 | J236: =COUNTIF(J6:J231,"C") -> 7 | K236: =COUNTIF(K6:K231,"C") -> 4 | L236: =COUNTIF(L6:L231,"C") -> 7 | ... AD236: =COUNTIF(AD6:AD231,"C") -> 0
B237: PROCESO B | E237: =COUNTIF(E6:E231,"B") -> 95 | F237: =COUNTIF(F6:F231,"B") -> 94 | G237: =COUNTIF(G6:G231,"B") -> 110 | H237: =COUNTIF(H6:H231,"B") -> 112 | I237: =COUNTIF(I6:I231,"B") -> 86 | J237: =COUNTIF(J6:J231,"B") -> 91 | K237: =COUNTIF(K6:K231,"B") -> 123 | L237: =COUNTIF(L6:L231,"B") -> 89 | ... AD237: =COUNTIF(AD6:AD231,"B") -> 219
B238: LOGRO A | E238: =COUNTIF(E6:E231,"A") -> 91 | F238: =COUNTIF(F6:F231,"A") -> 84 | G238: =COUNTIF(G6:G231,"A") -> 75 | H238: =COUNTIF(H6:H231,"A") -> 83 | I238: =COUNTIF(I6:I231,"A") -> 132 | J238: =COUNTIF(J6:J231,"A") -> 117 | K238: =COUNTIF(K6:K231,"A") -> 96 | L238: =COUNTIF(L6:L231,"A") -> 130 | ... AD238: =COUNTIF(AD6:AD231,"A") -> 0
B239: LOGRO DESTACADO AD | E239: =COUNTIF(E6:E231,"AD") -> 13 | F239: =COUNTIF(F6:F231,"AD") -> 5 | G239: =COUNTIF(G6:G231,"AD") -> 10 | H239: =COUNTIF(H6:H231,"AD") -> 14 | I239: =COUNTIF(I6:I231,"AD") -> 5 | J239: =COUNTIF(J6:J231,"AD") -> 11 | K239: =COUNTIF(K6:K231,"AD") -> 3 | L239: =COUNTIF(L6:L231,"AD") -> 0 | ... AD239: =COUNTIF(AD6:AD231,"AD") -> 0

Sheet Priorizados
C2: ESTUDIANTES PRIORIZADOS PARA REFORZAMIENTO - I BIMESTRE
C3: CANTIDAD DE COMPETENCIAS DESAPROBADAS
C6: N° | D6: =IE!C5 -> APELLIDOS Y NOMBRES DEL ESTUDIANTE | E6: =Reforzamiento!C5 -> GRADO | F6: =Reforzamiento!D5 -> SECCION | G6: =Reforzamiento!AE5 -> RR
B7: 1 | C7: 1 | D7: =IE!C104 -> PUMA QUISPE, FLOR GOYA | E7: =Reforzamiento!C104 -> 3 | F7: =Reforzamiento!D104 -> A | G7: =Reforzamiento!AE104 -> 14 | H7: N
B8: 2 | C8: 2 | D8: =IE!C95 -> CONDORI QUISPE, JHON MAXI | E8: =Reforzamiento!C95 -> 3 | F8: =Reforzamiento!D95 -> A | G8: =Reforzamiento!AE95 -> 12
B9: 3 | C9: 3 | D9: =IE!C56 -> OCHOA MAMANI, MARCO ANTONIO | E9: =Reforzamiento!C56 -> 2 | F9: =Reforzamiento!D56 -> A | G9: =Reforzamiento!AE56 -> 10
B10: 4 | C10: 4 | D10: =IE!C86 -> SANCA HUANACO, CHRIS JHOS | E10: =Reforzamiento!C86 -> 2 | F10: =Reforzamiento!D86 -> B | G10: =Reforzamiento!AE86 -> 10
B11: 5 | C11: 5 | D11: =IE!C195 -> HANCCO QUISPE, JUAN RODRIGO | E11: =Reforzamiento!C195 -> 5 | F11: =Reforzamiento!D195 -> A | G11: =Reforzamiento!AE195 -> 10
B12: 6 | C12: 6 | D12: =IE!C69 -> CALZADILLA TABEROA, JESUS ALEJANDRO | E12: =Reforzamiento!C69 -> 2 | F12: =Reforzamiento!D69 -> B | G12: =Reforzamiento!AE69 -> 9 | H12: N
B13: 7 | C13: 1 | D13: =IE!C7 -> ARCONDO HUAMAN, ISAAC RONALDINHO | E13: =Reforzamiento!C7 -> 1 | F13: =Reforzamiento!D7 -> A | G13: =Reforzamiento!AE7 -> 8 | H13: N
B14: 8 | C14: 2 | D14: =IE!C55 -> MANTILLA HUISA, JOSUE DAVID | E14: =Reforzamiento!C55 -> 2 | F14: =Reforzamiento!D55 -> A | G14: =Reforzamiento!AE55 -> 8
B15: 9 | C15: 3 | D15: =IE!C64 -> VILCA CAHUINA, FREDY MARLOM | E15: =Reforzamiento!C64 -> 2 | F15: =Reforzamiento!D64 -> A | G15: =Reforzamiento!AE64 -> 8
B16: 10 | C16: 4 | D16: =IE!C65 -> VILLANUEVA CHAVEZ, SAUL HERNAN | E16: =Reforzamiento!C65 -> 2 | F16: =Reforzamiento!D65 -> A | G16: =Reforzamiento!AE65 -> 8
B17: 11 | C17: 5 | D17: =IE!C97 -> FLORES CHUMBES, DANNY FRANK | E17: =Reforzamiento!C97 -> 3 | F17: =Reforzamiento!D97 -> A | G17: =Reforzamiento!AE97 -> 8
B18: 12 | C18: 6 | D18: =IE!C124 -> QUIJAHUAMAN HUARICALLO, DAYRON CHRISTIAN | E18: =Reforzamiento!C124 -> 3 | F18: =Reforzamiento!D124 -> B | G18: =Reforzamiento!AE124 -> 8
B19: 13 | C19: 7 | D19: =IE!C164 -> CRUZ QUICO, LUCIO MIGUEL | E19: =Reforzamiento!C164 -> 4 | F19: =Reforzamiento!D164 -> B | G19: =Reforzamiento!AE164 -> 8
B20: 14 | C20: 8 | D20: =IE!C17 -> OCHOA MAMANI, ARELÍ BETSAYDA | E20: =Reforzamiento!C17 -> 1 | F20: =Reforzamiento!D17 -> A | G20: =Reforzamiento!AE17 -> 7
B21: 15 | C21: 9 | D21: =IE!C47 -> CACERES JUAREZ, JHONNY IVAN | E21: =Reforzamiento!C47 -> 2 | F21: =Reforzamiento!D47 -> A | G21: =Reforzamiento!AE47 -> 7
B22: 16 | C22: 10 | D22: =IE!C90 -> TORRES CHOCO, MANUEL TONI | E22: =Reforzamiento!C90 -> 2 | F22: =Reforzamiento!D90 -> B | G22: =Reforzamiento!AE90 -> 7
B23: 17 | C23: 11 | D23: =IE!C203 -> MAMANI HUAYHUA, SALOME ESTRELLA | E23: =Reforzamiento!C203 -> 5 | F23: =Reforzamiento!D203 -> A | G23: =Reforzamiento!AE203 -> 7
B24: 18 | C24: 12 | D24: =IE!C67 -> YUCRA MENDOZA, YADIRA KAROL | E24: =Reforzamiento!C67 -> 2 | F24: =Reforzamiento!D67 -> A | G24: =Reforzamiento!AE67 -> 6 | H24: N
B25: 19 | C25: 13 | D25: =IE!C83 -> PAPEL HANCCO, JAIRO EDY | E25: =Reforzamiento!C83 -> 2 | F25: =Reforzamiento!D83 -> B | G25: =Reforzamiento!AE83 -> 6
B26: 20 | C26: 14 | D26: =IE!C100 -> HUAHUASONCCO HUACHO, ANALY YURIDI ANA | E26: =Reforzamiento!C100 -> 3 | F26: =Reforzamiento!D100 -> A | G26: =Reforzamiento!AE100 -> 6 | H26: N
B27: 21 | C27: 15 | D27: =IE!C166 -> GALARZA MAMANI, MAURICIO RENATO | E27: =Reforzamiento!C166 -> 4 | F27: =Reforzamiento!D166 -> B | G27: =Reforzamiento!AE166 -> 6
B28: 22 | C28: 16 | D28: =IE!C201 -> MAMANI CHALLCO, GEOBANI ANDERSON | E28: =Reforzamiento!C201 -> 5 | F28: =Reforzamiento!D201 -> A | G28: =Reforzamiento!AE201 -> 6
B29: 23 | C29: 17 | D29: =IE!C13 -> MAMANI CHALLCO, LENIN ANDRÉ | E29: =Reforzamiento!C13 -> 1 | F29: =Reforzamiento!D13 -> A | G29: =Reforzamiento!AE13 -> 5
B30: 24 | C30: 18 | D30: =IE!C19 -> PIZARRO CHARCA, FABRICIO NICOLAS | E30: =Reforzamiento!C19 -> 1 | F30: =Reforzamiento!D19 -> A | G30: =Reforzamiento!AE19 -> 5
B31: 25 | C31: 19 | D31: =IE!C52 -> GOMEZ HUAMANI, DANY GOEL | E31: =Reforzamiento!C52 -> 2 | F31: =Reforzamiento!D52 -> A | G31: =Reforzamiento!AE52 -> 5
B32: 26 | C32: 20 | D32: =IE!C57 -> PAUCAR HANAMPA, RONY GABRIEL | E32: =Reforzamiento!C57 -> 2 | F32: =Reforzamiento!D57 -> A | G32: =Reforzamiento!AE57 -> 5
B33: 27 | C33: 21 | D33: =IE!C62 -> VARGAS PAREDES, MILAGROS DEL CARMEN | E33: =Reforzamiento!C62 -> 2 | F33: =Reforzamiento!D62 -> A | G33: =Reforzamiento!AE62 -> 5 | H33: N
B34: 28 | C34: 22 | D34: =IE!C93 -> CAÑARI PUCHO, MAYKOL LEONARDO | E34: =Reforzamiento!C93 -> 3 | F34: =Reforzamiento!D93 -> A | G34: =Reforzamiento!AE93 -> 5
B35: 29 | C35: 23 | D35: =IE!C118 -> HUAYHUA CHOQUEHUANCA, BRAYAN JOSSIMAR | E35: =Reforzamiento!C118 -> 3 | F35: =Reforzamiento!D118 -> B | G35: =Reforzamiento!AE118 -> 5
B36: 30 | C36: 24 | D36: =IE!C125 -> QUISPE HUARACHA, FERNANDO JULIO | E36: =Reforzamiento!C125 -> 3 | F36: =Reforzamiento!D125 -> B | G36: =Reforzamiento!AE125 -> 5
B37: 31 | C37: 25 | D37: =IE!C141 -> LOPINTA HUAMANI, CLAUDIO YILMAR | E37: =Reforzamiento!C141 -> 4 | F37: =Reforzamiento!D141 -> A | G37: =Reforzamiento!AE141 -> 5
B38: 32 | C38: 26 | D38: =IE!C142 -> MOGROVEJO BOZA, JUAN DAVID | E38: =Reforzamiento!C142 -> 4 | F38: =Reforzamiento!D142 -> A | G38: =Reforzamiento!AE142 -> 5 | H38: N
B39: 33 | C39: 27 | D39: =IE!C154 -> ALEJO LUPINTA, DEISON FLEIDER | E39: =Reforzamiento!C154 -> 4 | F39: =Reforzamiento!D154 -> B | G39: =Reforzamiento!AE154 -> 5
B40: 34 | C40: 28 | D40: =IE!C171 -> MUCHA RIOS, LIAM ENRIQUE | E40: =Reforzamiento!C171 -> 4 | F40: =Reforzamiento!D171 -> B | G40: =Reforzamiento!AE171 -> 5 | H40: N
B41: 35 | C41: 29 | D41: =IE!C182 -> BALSA MAMANI, JAHIR ANDRE | E41: =Reforzamiento!C182 -> 5 | F41: =Reforzamiento!D182 -> A | G41: =Reforzamiento!AE182 -> 5
B42: 36 | C42: 30 | D42: =IE!C214 -> LANCHIPA CASQUINA, ELIAS JEREMIAS | E42: =Reforzamiento!C214 -> 5 | F42: =Reforzamiento!D214 -> B | G42: =Reforzamiento!AE214 -> 5
B43: 37 | C43: 31 | D43: =IE!C220 -> MOLINA TORRE, GERALDINE JAZMIN | E43: =Reforzamiento!C220 -> 5 | F43: =Reforzamiento!D220 -> B | G43: =Reforzamiento!AE220 -> 5 | H43: N
...

Sheet Salones
B2: EVALUACIÓN DIAGNÓSTICA INSTITUCIÓN EDUCATIVA: 40079 "Víctor Núñez Valencia" DISTRITO SACHACA
B3: Nivel de logro de las competencias
E4: MATEMÁTICA | I4: COMUNICACIÓN | L4: CIENCIA Y TECNOLOGÍA | O4: CIENCIAS SOCIALES | R4: DPCC | T4: EPT | U4: EDUCACIÓN FÍSICA | X4: ARTE Y CULTURA | Z4: INGLES | AC4: EDUCACIÓN RELIGIOSA
B5: APELLIDOS Y NOMBRES DEL ESTUDIANTE | C5: GRADO | D5: SECCION | E5: C1 | F5: C2 | G5: C3 | H5: C4 | I5: C1 | J5: C2 | K5: C3 | L5: C1 | M5: C2 | N5: C3 | O5: C1 | P5: C2 | Q5: C3 | R5: C1 | S5: C2 | T5: C1 | U5: C1 | V5: C2 | W5: C3 | X5: C1 | Y5: C2 | Z5: C1 | AA5: C2 | AB5: C3 | AC5: C1 | AD5: C2
A6: 1 | B6: ALEJO LUPINTA, DIANA ABIGAIL | C6: 1 | D6: A | E6: A | F6: A | G6: B | H6: A | I6: A | J6: A | K6: A | L6: A | M6: A | N6: A | O6: A | P6: B | Q6: B | R6: A | S6: A | T6: A | U6: A | V6: A | W6: A | X6: B | Y6: A | Z6: B | AA6: B | AB6: A | AC6: A | AD6: B
A7: 2 | B7: ARCONDO HUAMAN, ISAAC RONALDINHO | C7: 1 | D7: A | E7: B | F7: C | G7: B | H7: B | I7: B | J7: B | K7: B | L7: B | M7: B | N7: C | O7: B | P7: B | Q7: B | R7: C | S7: C | T7: B | U7: B | V7: B | W7: A | X7: B | Y7: A | Z7: C | AA7: C | AB7: C | AC7: C | AD7: B | AF7: AD | AG7: =COUNTIF(E6:AD23,"AD") -> 1
A8: 3 | B8: BALSA MAMANI, JHOSUE SAJAAT | C8: 1 | D8: A | E8: A | F8: A | G8: A | H8: A | I8: A | J8: A | K8: A | L8: A | M8: A | N8: A | O8: A | P8: A | Q8: B | R8: A | S8: A | T8: A | U8: A | V8: A | W8: A | X8: A | Y8: A | Z8: A | AA8: B | AB8: B | AC8: A | AD8: B | AF8: A | AG8: =COUNTIF(E6:AD23,"A") -> 192
A9: 4 | B9: CALANCHO MAMANI, RIZIERI BEAUTY | C9: 1 | D9: A | E9: A | F9: B | G9: B | H9: B | I9: A | J9: A | K9: A | L9: B | M9: B | N9: A | O9: A | P9: A | Q9: B | R9: A | S9: B | T9: A | U9: B | V9: A | W9: A | X9: B | Y9: A | Z9: B | AA9: B | AB9: B | AC9: A | AD9: B | AF9: B | AG9: =COUNTIF(E6:AD23,"B") -> 236
A10: 5 | B10: CHAMPE TACO, JUMY JAHAIRA | C10: 1 | D10: A | E10: B | F10: B | G10: B | H10: B | I10: A | J10: A | K10: A | L10: A | M10: B | N10: A | O10: B | P10: B | Q10: B | R10: A | S10: B | T10: B | U10: A | V10: B | W10: A | X10: B | Y10: A | Z10: B | AA10: B | AB10: C | AC10: B | AD10: B | AF10: C | AG10: =COUNTIF(E6:AD23,"C") -> 39
A11: 6 | B11: CUTI SENCIA, AIXA AYSEL | C11: 1 | D11: A | E11: A | F11: A | G11: A | H11: A | I11: A | J11: A | K11: A | L11: A | M11: A | N11: A | O11: A | P11: B | Q11: B | R11: A | S11: B | T11: B | U11: B | V11: A | W11: A | X11: A | Y11: B | Z11: B | AA11: B | AB11: B | AC11: B | AD11: B
A12: 7 | B12: HUACARPUMA SULCA, BRITNEY ESTEFANY | C12: 1 | D12: A | E12: A | F12: A | G12: B | H12: A | I12: A | J12: A | K12: A | L12: A | M12: A | N12: A | O12: A | P12: A | Q12: A | R12: A | S12: A | T12: B | U12: A | V12: A | W12: A | X12: A | Y12: A | Z12: A | AA12: B | AB12: A | AC12: B | AD12: B
A13: 8 | B13: MAMANI CHALLCO, LENIN ANDRÉ | C13: 1 | D13: A | E13: B | F13: C | G13: B | H13: B | I13: B | J13: B | K13: B | L13: B | M13: B | N13: B | O13: B | P13: B | Q13: B | R13: C | S13: B | T13: B | U13: A | V13: B | W13: A | X13: B | Y13: B | Z13: B | AA13: C | AB13: C | AC13: C | AD13: B
A14: 9 | B14: MANTILLA MAYTA, BELINDA MAJU | C14: 1 | D14: A | E14: B | F14: B | G14: C | H14: B | I14: A | J14: A | K14: A | L14: A | M14: B | N14: A | O14: B | P14: B | Q14: B | R14: B | S14: A | T14: B | U14: B | V14: A | W14: A | X14: B | Y14: A | Z14: B | AA14: B | AB14: C | AC14: A | AD14: B
A15: 10 | B15: MOROCCO CCALLO, YOSELIN RUTH | C15: 1 | D15: A | E15: B | F15: B | G15: B | H15: B | I15: B | J15: B | K15: B | L15: B | M15: B | N15: A | O15: B | P15: B | Q15: B | R15: A | S15: B | T15: B | U15: A | V15: A | W15: A | X15: B | Y15: A | Z15: B | AA15: B | AB15: C | AC15: B | AD15: B
A16: 11 | B16: NINA CHUMBES, ARIANA NIKOL | C16: 1 | D16: A | E16: B | F16: B | G16: B | H16: B | I16: A | J16: A | K16: A | L16: B | M16: B | N16: A | O16: B | P16: B | Q16: C | R16: B | S16: A | T16: B | U16: A | V16: B | W16: A | X16: A | Y16: A | Z16: B | AA16: B | AB16: C | AC16: B | AD16: B
A17: 12 | B17: OCHOA MAMANI, ARELÍ BETSAYDA | C17: 1 | D17: A | E17: B | F17: B | G17: B | H17: C | I17: B | J17: B | K17: B | L17: B | M17: B | N17: B | O17: B | P17: B | Q17: B | R17: C | S17: C | T17: B | U17: B | V17: B | W17: A | X17: A | Y17: A | Z17: C | AA17: C | AB17: C | AC17: C | AD17: B
A18: 13 | B18: PAPEL HANCCO, JHOSIMAR JHOJAN | C18: 1 | D18: A | E18: B | F18: B | G18: C | H18: B | I18: B | J18: B | K18: B | L18: B | M18: B | N18: B | O18: B | P18: B | Q18: B | R18: C | S18: C | T18: B | U18: B | V18: B | W18: A | X18: A | Y18: A | Z18: B | AA18: B | AB18: C | AC18: B | AD18: B
A19: 14 | B19: PIZARRO CHARCA, FABRICIO NICOLAS | C19: 1 | D19: A | E19: B | F19: C | G19: B | H19: B | I19: B | J19: B | K19: B | L19: B | M19: B | N19: B | O19: B | P19: B | Q19: B | R19: C | S19: C | T19: B | U19: A | V19: B | W19: A | X19: B | Y19: A | Z19: B | AA19: C | AB19: C | AC19: B | AD19: B
A20: 15 | B20: QUISPE YANA, TANIA ROSMERI | C20: 1 | D20: A | E20: B | F20: B | G20: B | H20: B | I20: B | J20: B | K20: B | L20: A | M20: B | N20: A | O20: B | P20: B | Q20: B | R20: A | S20: B | T20: B | U20: B | V20: A | W20: A | X20: A | Y20: A | Z20: B | AA20: B | AB20: C | AC20: A | AD20: B
A21: 16 | B21: SANDILLA PUMACALLAHUI, KRISTEL NAYSA | C21: 1 | D21: A | E21: B | F21: B | G21: B | H21: B | I21: A | J21: A | K21: A | L21: A | M21: A | N21: A | O21: A | P21: A | Q21: A | R21: A | S21: A | T21: A | U21: A | V21: A | W21: A | X21: A | Y21: A | Z21: A | AA21: B | AB21: A | AC21: A | AD21: B
A22: 17 | B22: VALLEJO APAZA, LUIS FERNANDO | C22: 1 | D22: A | E22: A | F22: A | G22: B | H22: A | I22: A | J22: A | K22: A | L22: A | M22: B | N22: A | O22: A | P22: A | Q22: B | R22: A | S22: A | T22: A | U22: A | V22: A | W22: A | X22: A | Y22: A | Z22: A | AA22: AD | AB22: A | AC22: A | AD22: B
... A26: 3 | B26: CASQUINO MOLLO, JUAN DIEGO | C26: 1 | D26: B | E26: B | F26: A | G26: B | H26: B | I26: B | J26: A | K26: B | L26: A | M26: A | N26: A | O26: A | P26: B | Q26: B | R26: A | S26: A | T26: B | U26: A | V26: A | W26: A | X26: A | Y26: A | Z26: A | AA26: B | AB26: B | AC26: A | AD26: B
A27: 4 | B27: CCALLA MAMANI, HARRINSON PAUL | C27: 1 | D27: B | E27: A | F27: A | G27: A | H27: A | I27: B | J27: B | K27: B | L27: B | M27: A | N27: A | O27: B | P27: B | Q27: B | R27: A | S27: A | T27: B | U27: A | V27: A | W27: A | X27: B | Y27: A | Z27: B | AA27: B | AB27: B | AC27: B | AD27: B | AF27: AD | AG27: =COUNTIF(E24:AD43,"AD") -> 2
A28: 5 | B28: CHANCOLLA SUCARI, JHON DREIK LIAM | C28: 1 | D28: B | E28: B | F28: B | G28: A | H28: B | I28: B | J28: B | K28: B | L28: A | M28: B | N28: A | O28: B | P28: B | Q28: B | R28: A | S28: A | T28: B | U28: A | V28: A | W28: A | X28: B | Y28: A | Z28: A | AA28: A | AB28: B | AC28: B | AD28: B | AF28: A | AG28: =COUNTIF(E24:AD43,"A") -> 288
A29: 6 | B29: CRUZ CALLASACA, MISHELL BRYANA | C29: 1 | D29: B | E29: A | F29: A | G29: B | H29: A | I29: B | J29: A | K29: B | L29: A | M29: B | N29: A | O29: B | P29: B | Q29: B | R29: B | S29: A | T29: B | U29: A | V29: A | W29: A | X29: A | Y29: A | Z29: A | AA29: A | AB29: A | AC29: B | AD29: B | AF29: B | AG29: =COUNTIF(E24:AD43,"B") -> 224
A30: 7 | B30: FLORES SUMERINDE, ANTHONNY CHRISTYAN | C30: 1 | D30: B | E30: B | F30: B | G30: A | H30: B | I30: A | J30: A | K30: B | L30: A | M30: B | N30: A | O30: A | P30: B | Q30: A | R30: A | S30: A | T30: B | U30: A | V30: A | W30: B | X30: A | Y30: A | Z30: A | AA30: A | AB30: A | AC30: B | AD30: B | AF30: C | AG30: =COUNTIF(E24:AD43,"C") -> 4
A31: 8 | B31: GALARZA QUISPE, LUZ YENNY | C31: 1 | D31: B | E31: A | F31: B | G31: B | H31: B | I31: A | J31: B | K31: B | L31: A | M31: B | N31: B | O31: B | P31: B | Q31: B | R31: A | S31: A | T31: A | U31: B | V31: A | W31: B | X31: B | Y31: A | Z31: A | AA31: A | AB31: A | AC31: A | AD31: B
A32: 9 | B32: HUARANCCA CONDORI, ALEXIS YOSUE | C32: 1 | D32: B | E32: A | F32: B | G32: B | H32: B | I32: B | J32: B | K32: A | L32: A | M32: A | N32: A | O32: A | P32: A | Q32: A | R32: A | S32: A | T32: B | U32: A | V32: A | W32: A | X32: A | Y32: A | Z32: B | AA32: B | AB32: B | AC32: B | AD32: B
A33: 10 | B33: LLERENA QUISPE, THIAGO ALESSANDRO | C33: 1 | D33: B | E33: A | F33: B | G33: A | H33: B | I33: B | J33: B | K33: B | L33: A | M33: A | N33: A | O33: B | P33: A | Q33: B | R33: A | S33: A | T33: A | U33: A | V33: A | W33: A | X33: A | Y33: A | Z33: B | AA33: B | AB33: A | AC33: A | AD33: B
A34: 11 | B34: MAMANI ARIAS, GABRIEL JESUS | C34: 1 | D34: B | E34: AD | F34: A | G34: A | H34: A | I34: A | J34: A | K34: A | L34: A | M34: A | N34: A | O34: A | P34: A | Q34: A | R34: A | S34: A | T34: A | U34: A | V34: A | W34: B | X34: A | Y34: A | Z34: A | AA34: A | AB34: A | AC34: A | AD34: B
A35: 12 | B35: MAMANI MENDOZA, BENYAMIN KEN | C35: 1 | D35: B | E35: A | F35: B | G35: A | H35: B | I35: A | J35: B | K35: B | L35: A | M35: A | N35: A | O35: A | P35: A | Q35: A | R35: A | S35: A | T35: A | U35: B | V35: A | W35: B | X35: B | Y35: A | Z35: B | AA35: B | AB35: B | AC35: B | AD35: B
A36: 13 | B36: MEDINA BEGAZO, GERHARD YOSHIRO | C36: 1 | D36: B | E36: B | F36: A | G36: B | H36: B | I36: A | J36: B | K36: B | L36: B | M36: A | N36: A | O36: B | P36: B | Q36: B | R36: B | S36: A | T36: A | U36: A | V36: A | W36: A | X36: A | Y36: A | Z36: A | AA36: A | AB36: B | AC36: B | AD36: B
A37: 14 | B37: MOLLO GONZALES, ESTHER JAZMÌN | C37: 1 | D37: B | E37: A | F37: A | G37: A | H37: A | I37: A | J37: A | K37: A | L37: A | M37: A | N37: A | O37: A | P37: A | Q37: A | R37: A | S37: A | T37: A | U37: B | V37: B | W37: A | X37: B | Y37: A | Z37: A | AA37: A | AB37: A | AC37: EXO | AD37: EXO
A38: 15 | B38: OCORURO FERNANDEZ, ROSENDO ADRIAN | C38: 1 | D38: B | E38: A | F38: B | G38: B | H38: A | I38: B | J38: B | K38: B | L38: A | M38: A | N38: A | O38: B | P38: B | Q38: B | R38: C | S38: B | T38: A | U38: A | V38: A | W38: A | X38: C | Y38: B | Z38: A | AA38: A | AB38: B | AC38: B | AD38: B
A39: 16 | B39: PACHA VILCA, VALENTINO RICARDO | C39: 1 | D39: B | E39: A | F39: B | G39: B | H39: B | I39: A | J39: B | K39: B | L39: B | M39: B | N39: A | O39: B | P39: B | Q39: B | R39: B | S39: B | T39: B | U39: A | V39: A | W39: B | X39: A | Y39: A | Z39: A | AA39: A | AB39: B | AC39: B | AD39: B
A40: 17 | B40: PERALTA QUISPE, MELANIA YIDDÁ | C40: 1 | D40: B | E40: B | F40: B | G40: B | H40: B | I40: A | J40: B | K40: B | L40: B | M40: A | N40: A | O40: B | P40: B | Q40: B | R40: A | S40: B | T40: A | U40: A | V40: A | W40: A | X40: B | Y40: A | Z40: A | AA40: A | AB40: B | AC40: B | AD40: B
A41: 18 | B41: PUCHO ALARCON, THIAGO JOSUE | C41: 1 | D41: B | E41: A | F41: B | G41: B | H41: B | I41: B | J41: B | K41: B | L41: A | M41: A | N41: A | O41: A | P41: B | Q41: A | R41: A | S41: A | T41: B | U41: B | V41: A | W41: A | X41: B | Y41: A | Z41: A | AA41: A | AB41: B | AC41: A | AD41: B
A42: 19 | B42: QUISPE QUISPE, CORINA DIANA | C42: 1 | D42: B | E42: A | F42: B | G42: B | H42: B | I42: B | J42: B | K42: B | L42: B | M42: A | N42: A | O42: B | P42: B | Q42: B | R42: A | S42: B | T42: A | U42: B | V42: A | W42: A | X42: A | Y42: A | Z42: B | AA42: C | AB42: B | AC42: B | AD42: B
... A48: 5 | B48: CALSIN MAMANI, CINDY ROMINA | C48: 2 | D48: A | E48: B | F48: B | G48: B | H48: B | I48: B | J48: B | K48: B | L48: B | M48: B | N48: A | O48: B | P48: B | Q48: B | R48: A | S48: B | T48: A | U48: A | V48: A | W48: A | X48: A | Y48: A | Z48: B | AA48: B | AB48: C | AC48: B | AD48: B
A49: 6 | B49: CCALLE CARDENAS, MARIANA DINA NIEVES | C49: 2 | D49: A | E49: A | F49: B | G49: A | H49: A | I49: A | J49: A | K49: A | L49: A | M49: A | N49: A | O49: A | P49: A | Q49: A | R49: A | S49: A | T49: A | U49: A | V49: A | W49: A | X49: A | Y49: A | Z49: A | AA49: A | AB49: A | AC49: A | AD49: B | AF49: AD | AG49: =COUNTIF(E44:AD67,"AD") -> 2
...
